Workbook

Sheet Start here
B2: UTL readiness assessment · working mockup v4
B4: What this is
B5: A clickable version of the product before it goes on the website. Answer the questions and the results write themselves, using the same rules the website would use.
B7: How to use it
B8: 1. Free test tab. Change the yellow answers (1 to 5). Sample answers are already filled in.
B9: 2. Free result tab. The score, the five area snapshot and the preview profile a free user would see.
B10: 3. Paid test tab. The 40 extra facet questions a paying user answers.
B11: 4. Paid report tab. The confirmed profile, top strengths, growth edges and working style.
B12: 5. Profile map tab. The six profiles in a grid, showing where the current answers land and why.
B13: 6. Score rubric tab. What the 0 to 100 score means, what good looks like, options for showing it, and the rules we sign off on.
B14: 7. Area rubrics tab. A definition for each of the five areas, and what Low, Mid and High look like at work.
B15: 8. Scoring rules tab. Every calculation step and the settings you can change, plus open questions for the pilot.
... B22: Scores use a simple 0 to 100 conversion and working cut points. The real version replaces these with norms from the Filipino pilot. Nothing here should be shown to a customer as a real result.

Sheet Free test
B2: Free readiness check · 20 questions
B3: Describe yourself as you generally are now, not as you wish to be. Pick a number in each yellow cell.
C4: 1 Very inaccurate · 2 Moderately inaccurate · 3 Neither · 4 Moderately accurate · 5 Very accurate
F5: Scoring (for review)
B6: # | C6: I… | D6: Your answer | F6: Area | G6: Key | H6: Scored | I6: Source
B7: 1 | C7: Am the life of the party. | D7: 3 | F7: Extraversion | G7: + | H7: =IF(D7="","",IF(G7="+",D7,6-D7)) -> 3 | I7: Mini-IPIP
B8: 2 | C8: Sympathize with others' feelings. | D8: 4 | F8: Agreeableness | G8: + | H8: =IF(D8="","",IF(G8="+",D8,6-D8)) -> 4 | I8: Mini-IPIP
B9: 3 | C9: Get chores done right away. | D9: 4 | F9: Conscientiousness | G9: + | H9: =IF(D9="","",IF(G9="+",D9,6-D9)) -> 4 | I9: Mini-IPIP
B10: 4 | C10: Have frequent mood swings. | D10: 2 | F10: Neuroticism | G10: + | H10: =IF(D10="","",IF(G10="+",D10,6-D10)) -> 2 | I10: Mini-IPIP
B11: 5 | C11: Have a vivid imagination. | D11: 4 | F11: Intellect | G11: + | H11: =IF(D11="","",IF(G11="+",D11,6-D11)) -> 4 | I11: Mini-IPIP
B12: 6 | C12: Don't talk a lot. | D12: 3 | F12: Extraversion | G12: - | H12: =IF(D12="","",IF(G12="+",D12,6-D12)) -> 3 | I12: Mini-IPIP
B13: 7 | C13: Am not interested in other people's problems. | D13: 2 | F13: Agreeableness | G13: - | H13: =IF(D13="","",IF(G13="+",D13,6-D13)) -> 4 | I13: Mini-IPIP
B14: 8 | C14: Often forget to put things back in their proper place. | D14: 2 | F14: Conscientiousness | G14: - | H14: =IF(D14="","",IF(G14="+",D14,6-D14)) -> 4 | I14: Mini-IPIP
B15: 9 | C15: Am relaxed most of the time. | D15: 4 | F15: Neuroticism | G15: - | H15: =IF(D15="","",IF(G15="+",D15,6-D15)) -> 2 | I15: Mini-IPIP
B16: 10 | C16: Am not interested in abstract ideas. | D16: 2 | F16: Intellect | G16: - | H16: =IF(D16="","",IF(G16="+",D16,6-D16)) -> 4 | I16: Mini-IPIP
B17: 11 | C17: Talk to a lot of different people at parties. | D17: 3 | F17: Extraversion | G17: + | H17: =IF(D17="","",IF(G17="+",D17,6-D17)) -> 3 | I17: Mini-IPIP
B18: 12 | C18: Feel others' emotions. | D18: 3 | F18: Agreeableness | G18: + | H18: =IF(D18="","",IF(G18="+",D18,6-D18)) -> 3 | I18: Mini-IPIP
... B26: 20 | C26: Do not have a good imagination. | D26: 2 | F26: Intellect | G26: - | H26: =IF(D26="","",IF(G26="+",D26,6-D26)) -> 4 | I26: Mini-IPIP
C28: Sample answers are filled in so you can see a result right away. Change any of them and the Free result tab updates.

Sheet Free result
B2: Your free readiness result
B3: =IF(COUNT('Free test'!$D$7:$D$26)<20,"Answered "&COUNT('Free test'!$D$7:$D$26)&" of 20. Finish all 20 for a complete result.","All 20 questions answered.") -> All 20 questions answered.
B5: Readiness score | C5: =IFERROR(ROUND(AVERAGE(C11,C12,C13),0),"") -> 79 | D5: =IFERROR(INDEX('Scoring rules'!$B$16:$B$19,MATCH(C5,'Scoring rules'!$C$16:$C$19,1)),"") -> Strong
B6: =IFERROR(INDEX('Write-ups'!$E$25:$E$28,MATCH(D5,'Write-ups'!$B$25:$B$28,0)),"") -> Most of the habits that matter are already in place. The next gains come from sharpening one or two specific areas.
B8: How you answered | C8: Score out of 100 | D8: Level | E8: What it means | H8: Working (for review) | I8: Average 1 to 5 | J8: Raw 0 to 100 | K8: Shown | L8: Rank helper
B9: Social energy | C9: =K9 -> 50 | D9: =IF(C9="","",IF(C9<'Scoring rules'!$C$7,"Low",IF(C9>'Scoring rules'!$C$8,"High","Mid"))) -> Mid | E9: =IFERROR(INDEX('Write-ups'!$E$7:$E$21,MATCH(B9&"|"&D9,'Write-ups'!$B$7:$B$21,0)),"") -> You can work a room when you need to and still enjoy time alone. Which way you lean depends on the day and the people. | H9: Extraversion | I9: =IFERROR(ROUND(AVERAGEIFS('Free test'!$H$7:$H$26,'Free test'!$F$7:$F$26,H9),2),"") -> 3 | J9: =IF(I9="","",ROUND((I9-1)/4*100,0)) -> 50 | K9: =J9 -> 50 | L9: =IF(K9="","",K9+ROW()/100000) -> 50.00009
B10: Warmth | C10: =K10 -> 75 | D10: =IF(C10="","",IF(C10<'Scoring rules'!$C$7,"Low",IF(C10>'Scoring rules'!$C$8,"High","Mid"))) -> High | E10: =IFERROR(INDEX('Write-ups'!$E$7:$E$21,MATCH(B10&"|"&D10,'Write-ups'!$B$7:$B$21,0)),"") -> You notice how people are feeling and you often act on it. Colleagues likely come to you when something is not going well. | H10: Agreeableness | I10: =IFERROR(ROUND(AVERAGEIFS('Free test'!$H$7:$H$26,'Free test'!$F$7:$F$26,H10),2),"") -> 4 | J10: =IF(I10="","",ROUND((I10-1)/4*100,0)) -> 75 | K10: =J10 -> 75 | L10: =IF(K10="","",K10+ROW()/100000) -> 75.0001
B11: Follow-through | C11: =K11 -> 81 | D11: =IF(C11="","",IF(C11<'Scoring rules'!$C$7,"Low",IF(C11>'Scoring rules'!$C$8,"High","Mid"))) -> High | E11: =IFERROR(INDEX('Write-ups'!$E$7:$E$21,MATCH(B11&"|"&D11,'Write-ups'!$B$7:$B$21,0)),"") -> You finish what you start and people can plan around you. Loose ends bother you more than they bother most people. | H11: Conscientiousness | I11: =IFERROR(ROUND(AVERAGEIFS('Free test'!$H$7:$H$26,'Free test'!$F$7:$F$26,H11),2),"") -> 4.25 | J11: =IF(I11="","",ROUND((I11-1)/4*100,0)) -> 81 | K11: =J11 -> 81 | L11: =IF(K11="","",K11+ROW()/100000) -> 81.00011
B12: Steadiness | C12: =K12 -> 75 | D12: =IF(C12="","",IF(C12<'Scoring rules'!$C$7,"Low",IF(C12>'Scoring rules'!$C$8,"High","Mid"))) -> High | E12: =IFERROR(INDEX('Write-ups'!$E$7:$E$21,MATCH(B12&"|"&D12,'Write-ups'!$B$7:$B$21,0)),"") -> You stay calm when things get loud. The people around you often borrow some of that calm without realizing it. | H12: Neuroticism | I12: =IFERROR(ROUND(AVERAGEIFS('Free test'!$H$7:$H$26,'Free test'!$F$7:$F$26,H12),2),"") -> 2 | J12: =IF(I12="","",ROUND((I12-1)/4*100,0)) -> 25 | K12: =IF(J12="","",100-J12) -> 75 | L12: =IF(K12="","",K12+ROW()/100000) -> 75.00012
B13: Curiosity | C13: =K13 -> 81 | D13: =IF(C13="","",IF(C13<'Scoring rules'!$C$7,"Low",IF(C13>'Scoring rules'!$C$8,"High","Mid"))) -> High | E13: =IFERROR(INDEX('Write-ups'!$E$7:$E$21,MATCH(B13&"|"&D13,'Write-ups'!$B$7:$B$21,0)),"") -> You enjoy complex problems and new ideas for their own sake. You may be the one still asking why after everyone else has moved on. | H13: Intellect | I13: =IFERROR(ROUND(AVERAGEIFS('Free test'!$H$7:$H$26,'Free test'!$F$7:$F$26,H13),2),"") -> 4.25 | J13: =IF(I13="","",ROUND((I13-1)/4*100,0)) -> 81 | K13: =J13 -> 81 | L13: =IF(K13="","",K13+ROW()/100000) -> 81.00013
H14: Steadiness shows 100 minus Neuroticism
B16: Your strongest area | C16: =IFERROR(INDEX($B$9:$B$13,MATCH(MAX($L$9:$L$13),$L$9:$L$13,0)),"") -> Curiosity
B17: =IFERROR(INDEX($E$9:$E$13,MATCH(MAX($L$9:$L$13),$L$9:$L$13,0)),"") -> You enjoy complex problems and new ideas for their own sake. You may be the one still asking why after everyone else has moved on. | H17: Profile working | I17: Value
H18: Voice score (Social energy) | I18: =C9 -> 50
B19: Your preview profile | C19: =IFERROR(INDEX('Write-ups'!$E$32:$E$37,MATCH(I25,'Write-ups'!$B$32:$B$37,0)),"") -> Go-getter | D19: =IFERROR(INDEX('Write-ups'!$I$32:$I$37,MATCH(I25,'Write-ups'!$B$32:$B$37,0)),"") -> Driven, practical, adaptable | H19: Voice | I19: =IF(I18="","",IF(I18<'Scoring rules'!$C$9,"Reserved",IF(I18>'Scoring rules'!$C$10,"Vocal","Balanced"))) -> Balanced
B20: =IFERROR(INDEX('Write-ups'!$H$32:$H$37,MATCH(I25,'Write-ups'!$B$32:$B$37,0)),"") -> You push hard for results and still read the room well enough to know when to ease off. | H20: Achievement side (Follow-through) | I20: =C11 -> 81
B21: Where you add the most | C21: =IFERROR(INDEX('Write-ups'!$F$32:$F$37,MATCH(I25,'Write-ups'!$B$32:$B$37,0)),"") -> Goals that need both push and judgment. You know when to press and when to wait. | H21: Connection side (Warmth) | I21: =C10 -> 75
B22: What to watch | C22: =IFERROR(INDEX('Write-ups'!$G$32:$G$37,MATCH(I25,'Write-ups'!$B$32:$B$37,0)),"") -> You may try to play both roles at once. Decide which one the moment actually needs. | H22: Drive | I22: =IF(OR(I20="",I21=""),"",IF(I20>=I21,"Achievement-driven","Connection-driven")) -> Achievement-driven
B23: ="This is a preview from 20 questions. The full report confirms it using 40 more."&IF(I24="Yes"," Your Drive result was a close call, so the facet questions matter more than usual for you.","") -> This is a preview from 20 questions. The full report confirms it using 40 more. Your Drive result was a close call, so the facet questions matter more than usual for you. | H23: Gap between the two | I23: =IF(OR(I20="",I21=""),"",ABS(I20-I21)) -> 6
H24: Close call | I24: =IF(I23="","",IF(I23<'Scoring rules'!$C$11,"Yes","No")) -> Yes
H25: Profile key | I25: =I19&"|"&I22 -> Balanced|Achievement-driven
B26: ='Write-ups'!$E$65 -> Want the full picture? The paid report adds 40 questions and breaks your result into 10 facets. It confirms your profile and names your top two strengths and your top two growth edges.

Sheet Paid test
B2: Full facet report · 40 more questions
B3: Same instructions as the free check. These questions break your result into 10 facets.
C4: 1 Very inaccurate · 2 Moderately inaccurate · 3 Neither · 4 Moderately accurate · 5 Very accurate
F5: Scoring (for review)
B6: # | C6: I… | D6: Your answer | F6: Facet | G6: Key | H6: Scored | I6: Source
B7: 21 | C7: Go straight for the goal. | D7: 5 | F7: Achievement-Striving | G7: + | H7: =IF(D7="","",IF(G7="+",D7,6-D7)) -> 5 | I7: IPIP NEO facet scale
B8: 22 | C8: Start tasks right away. | D8: 4 | F8: Self-Discipline | G8: + | H8: =IF(D8="","",IF(G8="+",D8,6-D8)) -> 4 | I8: IPIP NEO facet scale
B9: 23 | C9: Like to tidy up. | D9: 4 | F9: Orderliness | G9: + | H9: =IF(D9="","",IF(G9="+",D9,6-D9)) -> 4 | I9: IPIP NEO facet scale
B10: 24 | C10: Like to solve complex problems. | D10: 5 | F10: Intellect | G10: + | H10: =IF(D10="","",IF(G10="+",D10,6-D10)) -> 5 | I10: IPIP NEO facet scale
B11: 25 | C11: Worry about things. | D11: 3 | F11: Anxiety | G11: + | H11: =IF(D11="","",IF(G11="+",D11,6-D11)) -> 3 | I11: IPIP NEO facet scale
B12: 26 | C12: Am easily intimidated. | D12: 2 | F12: Self-Consciousness | G12: + | H12: =IF(D12="","",IF(G12="+",D12,6-D12)) -> 2 | I12: IPIP NEO facet scale
B13: 27 | C13: Take charge. | D13: 4 | F13: Assertiveness | G13: + | H13: =IF(D13="","",IF(G13="+",D13,6-D13)) -> 4 | I13: IPIP NEO facet scale
B14: 28 | C14: Am always busy. | D14: 5 | F14: Activity Level | G14: + | H14: =IF(D14="","",IF(G14="+",D14,6-D14)) -> 5 | I14: IPIP NEO facet scale
B15: 29 | C15: Am easy to satisfy. | D15: 3 | F15: Cooperation | G15: + | H15: =IF(D15="","",IF(G15="+",D15,6-D15)) -> 3 | I15: IPIP NEO facet scale
B16: 30 | C16: Love to help others. | D16: 4 | F16: Altruism | G16: + | H16: =IF(D16="","",IF(G16="+",D16,6-D16)) -> 4 | I16: IPIP NEO facet scale
B17: 31 | C17: Work hard. | D17: 4 | F17: Achievement-Striving | G17: + | H17: =IF(D17="","",IF(G17="+",D17,6-D17)) -> 4 | I17: IPIP NEO facet scale
B18: 32 | C18: Carry out my plans. | D18: 4 | F18: Self-Discipline | G18: + | H18: =IF(D18="","",IF(G18="+",D18,6-D18)) -> 4 | I18: IPIP NEO facet scale
... B46: 60 | C46: Take no time for others. | D46: 2 | F46: Altruism | G46: - | H46: =IF(D46="","",IF(G46="+",D46,6-D46)) -> 4 | I46: IPIP NEO facet scale

Sheet Paid report
B2: Your full readiness report
B3: =IF(COUNT('Paid test'!$D$7:$D$46)<40,"Answered "&COUNT('Paid test'!$D$7:$D$46)&" of 40. Finish all 40 for a complete report.","All 40 facet questions answered.") -> All 40 facet questions answered.
B5: Readiness score | C5: =IFERROR(ROUND(AVERAGE(H30:H35),0),"") -> 71 | D5: =IFERROR(INDEX('Scoring rules'!$B$16:$B$19,MATCH(C5,'Scoring rules'!$C$16:$C$19,1)),"") -> Strong | G5: =IF('Free result'!C5="","","Free preview score was "&'Free result'!C5) -> Free preview score was 79
B6: =IFERROR(INDEX('Write-ups'!$E$25:$E$28,MATCH(D5,'Write-ups'!$B$25:$B$28,0)),"") -> Most of the habits that matter are already in place. The next gains come from sharpening one or two specific areas.
G7: Profile working | H7: Value
B8: Your confirmed profile | C8: =IFERROR(INDEX('Write-ups'!$E$32:$E$37,MATCH(H15,'Write-ups'!$B$32:$B$37,0)),"") -> Natural leader | D8: =IFERROR(INDEX('Write-ups'!$I$32:$I$37,MATCH(H15,'Write-ups'!$B$32:$B$37,0)),"") -> Decisive, confident, ambitious | G8: Voice score (Assertiveness) | H8: =INDEX($D$30:$D$39,MATCH("Assertiveness",$B$30:$B$39,0)) -> 75
B9: =IFERROR(INDEX('Write-ups'!$H$32:$H$37,MATCH(H15,'Write-ups'!$B$32:$B$37,0)),"") -> You go first and set the pace. Other people often take their cue from you. | G9: Voice | H9: =IF(H8="","",IF(H8<'Scoring rules'!$C$9,"Reserved",IF(H8>'Scoring rules'!$C$10,"Vocal","Balanced"))) -> Vocal
B10: Where you add the most | C10: =IFERROR(INDEX('Write-ups'!$F$32:$F$37,MATCH(H15,'Write-ups'!$B$32:$B$37,0)),"") -> New projects and moments that need someone to go first. | G10: Achievement-Striving | H10: =INDEX($D$30:$D$39,MATCH("Achievement-Striving",$B$30:$B$39,0)) -> 88
B11: What to watch | C11: =IFERROR(INDEX('Write-ups'!$G$32:$G$37,MATCH(H15,'Write-ups'!$B$32:$B$37,0)),"") -> Others may wait for you instead of stepping up. Leave room for them to lead. | G11: Altruism | H11: =INDEX($D$30:$D$39,MATCH("Altruism",$B$30:$B$39,0)) -> 69
B12: =IF(C8="","",IF(C8='Free result'!C19,"This matches your free preview.","Your free preview showed "&'Free result'!C19&". The facet questions refined it to "&C8&".")) -> Your free preview showed Go-getter. The facet questions refined it to Natural leader. | G12: Drive | H12: =IF(OR(H10="",H11=""),"",IF(H10>=H11,"Achievement-driven","Connection-driven")) -> Achievement-driven
G13: Gap between the two | H13: =IF(OR(H10="",H11=""),"",ABS(H10-H11)) -> 19
B14: Your top strengths | G14: Close call | H14: =IF(H13="","",IF(H13<'Scoring rules'!$C$11,"Yes","No")) -> No
B15: =IFERROR(INDEX($B$30:$B$35,MATCH(LARGE($I$30:$I$35,1),$I$30:$I$35,0)),"") -> Achievement-Striving | C15: =IFERROR(INDEX('Write-ups'!$E$41:$E$46,MATCH(B15,'Write-ups'!$B$41:$B$46,0)),"") -> You set a high bar for your own work and keep pushing toward it. | G15: Profile key | H15: =H9&"|"&H12 -> Vocal|Achievement-driven
B16: =IFERROR(INDEX($B$30:$B$35,MATCH(LARGE($I$30:$I$35,2),$I$30:$I$35,0)),"") -> Intellect | C16: =IFERROR(INDEX('Write-ups'!$E$41:$E$46,MATCH(B16,'Write-ups'!$B$41:$B$46,0)),"") -> You enjoy hard problems and can hold a lot of information at once.
B18: Your growth edges
B19: =IFERROR(INDEX($B$30:$B$35,MATCH(SMALL($I$30:$I$35,1),$I$30:$I$35,0)),"") -> Anxiety | C19: =IFERROR(INDEX('Write-ups'!$F$41:$F$46,MATCH(B19,'Write-ups'!$B$41:$B$46,0)),"") -> A tense meeting can stay with you longer than it should.
B20: =IFERROR(INDEX($B$30:$B$35,MATCH(SMALL($I$30:$I$35,2),$I$30:$I$35,0)),"") -> Self-Discipline | C20: =IFERROR(INDEX('Write-ups'!$F$41:$F$46,MATCH(B20,'Write-ups'!$B$41:$B$46,0)),"") -> Structure helps you more than open-ended ownership does.
B22: Your working style | C22: Style facets describe how you work. No level is better than another.
B23: Assertiveness | C23: =INDEX($E$30:$E$39,MATCH(B23,$B$30:$B$39,0)) -> High | D23: =IFERROR(INDEX('Write-ups'!$E$50:$E$61,MATCH(B23&"|"&C23,'Write-ups'!$B$50:$B$61,0)),"") -> You take charge easily and people often look to you to set direction.
B24: Activity Level | C24: =INDEX($E$30:$E$39,MATCH(B24,$B$30:$B$39,0)) -> High | D24: =IFERROR(INDEX('Write-ups'!$E$50:$E$61,MATCH(B24&"|"&C24,'Write-ups'!$B$50:$B$61,0)),"") -> You like a full calendar and move fast between tasks.
B25: Cooperation | C25: =INDEX($E$30:$E$39,MATCH(B25,$B$30:$B$39,0)) -> Mid | D25: =IFERROR(INDEX('Write-ups'!$E$50:$E$61,MATCH(B25&"|"&C25,'Write-ups'!$B$50:$B$61,0)),"") -> You pick your battles and avoid conflict that does not matter.
B26: Altruism | C26: =INDEX($E$30:$E$39,MATCH(B26,$B$30:$B$39,0)) -> High | D26: =IFERROR(INDEX('Write-ups'!$E$50:$E$61,MATCH(B26&"|"&C26,'Write-ups'!$B$50:$B$61,0)),"") -> You go out of your way for others, often before they ask.
B28: All 10 facets
B29: Facet | C29: Group | D29: Score out of 100 | E29: Level | G29: Average 1 to 5 | H29: Readiness value | I29: Rank helper
B30: Achievement-Striving | C30: Readiness | D30: =IF(G30="","",ROUND((G30-1)/4*100,0)) -> 88 | E30: =IF(D30="","",IF(D30<'Scoring rules'!$C$7,"Low",IF(D30>'Scoring rules'!$C$8,"High","Mid"))) -> High | G30: =IFERROR(ROUND(AVERAGEIFS('Paid test'!$H$7:$H$46,'Paid test'!$F$7:$F$46,B30),2),"") -> 4.5 | H30: =D30 -> 88 | I30: =IF(H30="","",H30+ROW()/100000) -> 88.0003
B31: Self-Discipline | C31: Readiness | D31: =IF(G31="","",ROUND((G31-1)/4*100,0)) -> 63 | E31: =IF(D31="","",IF(D31<'Scoring rules'!$C$7,"Low",IF(D31>'Scoring rules'!$C$8,"High","Mid"))) -> High | G31: =IFERROR(ROUND(AVERAGEIFS('Paid test'!$H$7:$H$46,'Paid test'!$F$7:$F$46,B31),2),"") -> 3.5 | H31: =D31 -> 63 | I31: =IF(H31="","",H31+ROW()/100000) -> 63.00031
B32: Orderliness | C32: Readiness | D32: =IF(G32="","",ROUND((G32-1)/4*100,0)) -> 75 | E32: =IF(D32="","",IF(D32<'Scoring rules'!$C$7,"Low",IF(D32>'Scoring rules'!$C$8,"High","Mid"))) -> High | G32: =IFERROR(ROUND(AVERAGEIFS('Paid test'!$H$7:$H$46,'Paid test'!$F$7:$F$46,B32),2),"") -> 4 | H32: =D32 -> 75 | I32: =IF(H32="","",H32+ROW()/100000) -> 75.00032
B33: Intellect | C33: Readiness | D33: =IF(G33="","",ROUND((G33-1)/4*100,0)) -> 81 | E33: =IF(D33="","",IF(D33<'Scoring rules'!$C$7,"Low",IF(D33>'Scoring rules'!$C$8,"High","Mid"))) -> High | G33: =IFERROR(ROUND(AVERAGEIFS('Paid test'!$H$7:$H$46,'Paid test'!$F$7:$F$46,B33),2),"") -> 4.25 | H33: =D33 -> 81 | I33: =IF(H33="","",H33+ROW()/100000) -> 81.00033
B34: Anxiety | C34: Readiness, read inversely | D34: =IF(G34="","",ROUND((G34-1)/4*100,0)) -> 50 | E34: =IF(D34="","",IF(D34<'Scoring rules'!$C$7,"Low",IF(D34>'Scoring rules'!$C$8,"High","Mid"))) -> Mid | G34: =IFERROR(ROUND(AVERAGEIFS('Paid test'!$H$7:$H$46,'Paid test'!$F$7:$F$46,B34),2),"") -> 3 | H34: =IF(D34="","",100-D34) -> 50 | I34: =IF(H34="","",H34+ROW()/100000) -> 50.00034
B35: Self-Consciousness | C35: Readiness, read inversely | D35: =IF(G35="","",ROUND((G35-1)/4*100,0)) -> 31 | E35: =IF(D35="","",IF(D35<'Scoring rules'!$C$7,"Low",IF(D35>'Scoring rules'!$C$8,"High","Mid"))) -> Low | G35: =IFERROR(ROUND(AVERAGEIFS('Paid test'!$H$7:$H$46,'Paid test'!$F$7:$F$46,B35),2),"") -> 2.25 | H35: =IF(D35="","",100-D35) -> 69 | I35: =IF(H35="","",H35+ROW()/100000) -> 69.00035
B36: Assertiveness | C36: Style, the Voice axis | D36: =IF(G36="","",ROUND((G36-1)/4*100,0)) -> 75 | E36: =IF(D36="","",IF(D36<'Scoring rules'!$C$7,"Low",IF(D36>'Scoring rules'!$C$8,"High","Mid"))) -> High | G36: =IFERROR(ROUND(AVERAGEIFS('Paid test'!$H$7:$H$46,'Paid test'!$F$7:$F$46,B36),2),"") -> 4
B37: Activity Level | C37: Style | D37: =IF(G37="","",ROUND((G37-1)/4*100,0)) -> 81 | E37: =IF(D37="","",IF(D37<'Scoring rules'!$C$7,"Low",IF(D37>'Scoring rules'!$C$8,"High","Mid"))) -> High | G37: =IFERROR(ROUND(AVERAGEIFS('Paid test'!$H$7:$H$46,'Paid test'!$F$7:$F$46,B37),2),"") -> 4.25
B38: Cooperation | C38: Style | D38: =IF(G38="","",ROUND((G38-1)/4*100,0)) -> 56 | E38: =IF(D38="","",IF(D38<'Scoring rules'!$C$7,"Low",IF(D38>'Scoring rules'!$C$8,"High","Mid"))) -> Mid | G38: =IFERROR(ROUND(AVERAGEIFS('Paid test'!$H$7:$H$46,'Paid test'!$F$7:$F$46,B38),2),"") -> 3.25
B39: Altruism | C39: Style, the Drive axis | D39: =IF(G39="","",ROUND((G39-1)/4*100,0)) -> 69 | E39: =IF(D39="","",IF(D39<'Scoring rules'!$C$7,"Low",IF(D39>'Scoring rules'!$C$8,"High","Mid"))) -> High | G39: =IFERROR(ROUND(AVERAGEIFS('Paid test'!$H$7:$H$46,'Paid test'!$F$7:$F$46,B39),2),"") -> 3.75
G40: Anxiety and Self-Consciousness count as 100 minus their score
B42: ='Write-ups'!$E$66 -> The Think, Speak, and Act Like an Executive™ cohort is built around these habits. Join the waitlist to hear when the next cohort opens.

Sheet Profile map
B2: Profile map
B3: The six profiles, where people land and how the current answers get there.
B5: The six profiles
B6: Profile | C6: In a few words | D6: How someone gets here | F6: Description | G6: Other names to test
B7: Quiet achiever | C7: Focused, self-driven, reliable | D7: ="Voice below "&'Scoring rules'!$C$9&", achievement side at or above connection side" -> Voice below 40, achievement side at or above connection side | F7: You put in the work before anyone asks. People know you by what you finish, not by how much you talk about it. | G7: Heads-down doer · Self-starter
B8: Steady supporter | C8: Calm, dependable, loyal | D8: ="Voice below "&'Scoring rules'!$C$9&", connection side above achievement side" -> Voice below 40, connection side above achievement side | F8: People lean on you when things get hard. You do not need the spotlight to make a team work better. | G8: Calm and dependable · Rock of the team
B9: Go-getter | C9: Driven, practical, adaptable | D9: ="Voice "&'Scoring rules'!$C$9&" to "&'Scoring rules'!$C$10&", achievement side at or above connection side" -> Voice 40 to 60, achievement side at or above connection side | F9: You push hard for results and still read the room well enough to know when to ease off. | G9: Driven all-rounder · Doer
B10: Team player | C10: Cooperative, fair, easy to work with | D10: ="Voice "&'Scoring rules'!$C$9&" to "&'Scoring rules'!$C$10&", connection side above achievement side" -> Voice 40 to 60, connection side above achievement side | F10: You keep a group working together. You often notice what two people missed about each other. | G10: Collaborator · Connector
B11: Natural leader | C11: Decisive, confident, ambitious | D11: ="Voice above "&'Scoring rules'!$C$10&", achievement side at or above connection side" -> Voice above 60, achievement side at or above connection side | F11: You go first and set the pace. Other people often take their cue from you. | G11: Take-charge type · Trailblazer
B12: People person | C12: Outgoing, warm, encouraging | D12: ="Voice above "&'Scoring rules'!$C$10&", connection side above achievement side" -> Voice above 60, connection side above achievement side | F12: You bring energy into a room and get people talking to each other, not only to you. | G12: Motivator · Energizer
B13: Pilot idea: before showing a result, ask people to pick which of the three names in each row fits them best. The name most people choose for themselves becomes the final name.
B16: Where people land | C16: Gold boxes show where the current answers land.
C17: Achievement-driven Achievement side scores higher | D17: Connection-driven Connection side scores higher | I17: Free preview key | J17: ='Free result'!I25 -> Balanced|Achievement-driven | K17: Box keys (for review)
B18: ="Reserved"&CHAR(10)&"Voice score below "&'Scoring rules'!$C$9 -> Reserved Voice score below 40 | C18: =INDEX('Write-ups'!$E$32:$E$37,MATCH(K18,'Write-ups'!$B$32:$B$37,0))&CHAR(10)&INDEX('Write-ups'!$I$32:$I$37,MATCH(K18,'Write-ups'!$B$32:$B$37,0))&IF(K18=$J$17,CHAR(10)&"Free preview lands here","")&IF(K18=$J$18,CHAR(10)&"Full report lands here","") -> Quiet achiever Focused, self-driven, reliable | D18: =INDEX('Write-ups'!$E$32:$E$37,MATCH(L18,'Write-ups'!$B$32:$B$37,0))&CHAR(10)&INDEX('Write-ups'!$I$32:$I$37,MATCH(L18,'Write-ups'!$B$32:$B$37,0))&IF(L18=$J$17,CHAR(10)&"Free preview lands here","")&IF(L18=$J$18,CHAR(10)&"Full report lands here","") -> Steady supporter Calm, dependable, loyal | I18: Full report key | J18: ='Paid report'!H15 -> Vocal|Achievement-driven | K18: Reserved|Achievement-driven | L18: Reserved|Connection-driven
B19: ="Balanced"&CHAR(10)&"Voice score "&'Scoring rules'!$C$9&" to "&'Scoring rules'!$C$10 -> Balanced Voice score 40 to 60 | C19: =INDEX('Write-ups'!$E$32:$E$37,MATCH(K19,'Write-ups'!$B$32:$B$37,0))&CHAR(10)&INDEX('Write-ups'!$I$32:$I$37,MATCH(K19,'Write-ups'!$B$32:$B$37,0))&IF(K19=$J$17,CHAR(10)&"Free preview lands here","")&IF(K19=$J$18,CHAR(10)&"Full report lands here","") -> Go-getter Driven, practical, adaptable Free preview lands here | D19: =INDEX('Write-ups'!$E$32:$E$37,MATCH(L19,'Write-ups'!$B$32:$B$37,0))&CHAR(10)&INDEX('Write-ups'!$I$32:$I$37,MATCH(L19,'Write-ups'!$B$32:$B$37,0))&IF(L19=$J$17,CHAR(10)&"Free preview lands here","")&IF(L19=$J$18,CHAR(10)&"Full report lands here","") -> Team player Cooperative, fair, easy to work with | K19: Balanced|Achievement-driven | L19: Balanced|Connection-driven
B20: ="Vocal"&CHAR(10)&"Voice score above "&'Scoring rules'!$C$10 -> Vocal Voice score above 60 | C20: =INDEX('Write-ups'!$E$32:$E$37,MATCH(K20,'Write-ups'!$B$32:$B$37,0))&CHAR(10)&INDEX('Write-ups'!$I$32:$I$37,MATCH(K20,'Write-ups'!$B$32:$B$37,0))&IF(K20=$J$17,CHAR(10)&"Free preview lands here","")&IF(K20=$J$18,CHAR(10)&"Full report lands here","") -> Natural leader Decisive, confident, ambitious Full report lands here | D20: =INDEX('Write-ups'!$E$32:$E$37,MATCH(L20,'Write-ups'!$B$32:$B$37,0))&CHAR(10)&INDEX('Write-ups'!$I$32:$I$37,MATCH(L20,'Write-ups'!$B$32:$B$37,0))&IF(L20=$J$17,CHAR(10)&"Free preview lands here","")&IF(L20=$J$18,CHAR(10)&"Full report lands here","") -> People person Outgoing, warm, encouraging | K20: Vocal|Achievement-driven | L20: Vocal|Connection-driven
B23: How the current answers map
B24: Step | C24: Free preview (20 questions) | D24: Full report (60 questions)
B25: Voice score comes from | C25: Social energy | D25: Assertiveness
B26: Voice score | C26: ='Free result'!I18 -> 50 | D26: ='Paid report'!H8 -> 75
B27: Voice | C27: ='Free result'!I19 -> Balanced | D27: ='Paid report'!H9 -> Vocal
B28: Achievement side comes from | C28: Follow-through | D28: Achievement-Striving
B29: Achievement side score | C29: ='Free result'!I20 -> 81 | D29: ='Paid report'!H10 -> 88
B30: Connection side comes from | C30: Warmth | D30: Altruism
B31: Connection side score | C31: ='Free result'!I21 -> 75 | D31: ='Paid report'!H11 -> 69
B32: Drive | C32: ='Free result'!I22 -> Achievement-driven | D32: ='Paid report'!H12 -> Achievement-driven
B33: Close call on Drive | C33: ='Free result'!I24 -> Yes | D33: ='Paid report'!H14 -> No
B34: Profile | C34: ='Free result'!C19 -> Go-getter | D34: ='Paid report'!C8 -> Natural leader

Sheet Score rubric
B2: Readiness score rubric
B3: What the 0 to 100 readiness score means, what good looks like, and the rules we agree to before launch.
B5: What the readiness score is
B6: What it measures | C6: How often you describe yourself doing the things that carry people into bigger roles: finishing what you start, staying clear under pressure and going after hard problems.
B7: What goes into it | C7: Free check: the plain average of Follow-through, Steadiness and Curiosity. Full report: the plain average of six facets, which are Achievement-Striving, Self-Discipline, Orderliness, Intellect, Anxiety (flipped) and Self-Consciousness (flipped).
B8: What it is not | C8: A test of ability, an IQ score or a pass mark. It is how you describe yourself today, and it moves as your habits change.
B9: Why two areas are left out | C9: Social energy and Warmth are useful at both ends. A quiet leader and a loud one can both be ready. These two shape your profile instead of your score.
B10: What a 100 means | C10: The top answer on every readiness question. It is the edge of the scale, not the goal. 80 and above is already the top band, and a score above 90 is worth checking against how colleagues see you.
B13: Band rubric
B14: Band | C14: Score range | D14: Answers that produce it | E14: What it looks like at work | F14: What we suggest next | G14: How we say it
B15: Emerging | C15: ='Scoring rules'!C16&" to "&('Scoring rules'!C17-1) -> 0 to 39 | D15: Readiness answers average below 2.6, after reversed statements are flipped. Mostly Neither or Inaccurate on the strong-habit statements. | E15: You often need a deadline or a reminder to finish. Pressure can knock your thinking off course. You tend to stick with the familiar way. | F15: Pick one area and one habit for the next 30 days. The area with the lowest score is usually the best place to start. | G15: Name one starting point. Never list everything that is low. Show how many points to Developing.
B16: Developing | C16: ='Scoring rules'!C17&" to "&('Scoring rules'!C18-1) -> 40 to 59 | D16: Readiness answers average from 2.6 up to 3.4. A mix of Neither and Moderately accurate. | E16: You are dependable on most things. One area, often steadiness under pressure or finishing without being chased, slows you down. | F16: Close the one gap that would move your score the most. The result names it. | G16: Lead with what is already working, then name the one gap.
B17: Strong | C17: ='Scoring rules'!C18&" to "&('Scoring rules'!C19-1) -> 60 to 79 | D17: Readiness answers average from 3.4 up to 4.2. Mostly Moderately accurate. | E17: People count on you. You stay clear in most tense moments and take on hard problems. | F17: Sharpen one area and take on one piece of stretch work, such as leading a meeting or owning a project end to end. | G17: Confirm the habits are there. Point to the next step up, not to what is missing.
B18: Exceptional | C18: ='Scoring rules'!C19&" to 100" -> 80 to 100 | D18: Readiness answers average 4.2 or higher. Moderately accurate across the board, with several Very accurate. | E18: You finish without being chased, stay calm when things get loud, and go after hard problems. | F18: Point these habits at a bigger role. Watch for overuse, such as holding on to plans or taking on too much yourself. | G18: Say plainly that the habits are there. If the score is above 90, add that very high self-ratings are worth checking with people who work with you.
B19: Score ranges read the cut points from the Scoring rules tab, so changing them there updates this table. The answer averages in column D are for the current cut points (40, 60, 80).
B21: Should we show the number? Options for the result page
B22: Option | C22: Recommend | D22: What the person sees | E22: Upside | F22: Risk
B23: A. Number first (what the preview does now) | C23: No | D23: A big 0 to 100 dial, then the band and profile. | E23: Clear and easy to share. Easy to compare on a retake. | F23: Reads like a school grade. In the Philippines 75 is often the passing mark, so a 46 can read as failing even though there is no pass mark.
B24: B. Band first, number second (recommended) | C24: Yes | D24: The band name large, the number smaller, and a line such as 14 points to Strong, with the one area that would move it most. | E24: Turns the number into a next step. People still see progress on a retake. | F24: The band name still has to feel fair at the low end.
B25: C. Band only in the free check, number in the full report | C25: Fallback if pilot takers say the number feels harsh | D25: Free takers see the band and profile. The number appears only in the paid report. | E25: Softest landing. Gives the paid report something extra. | F25: Free takers cannot see small changes on a retake.
B26: D. Percentile after the pilot | C26: Later, as a second line | D26: Higher than 62% of Filipino professionals who took it. | E26: Most honest comparison once we have the data. | F26: Needs at least 200 finished tests before it means anything. A low percentile can sting more than a low score.
B28: Rules we agree on
B29: Rule 1 | C29: The score describes habits people say they have today. It is not a grade, an IQ score or a pass mark.
B30: Rule 2 | C30: There is no passing score. Every band gets a next step.
B31: Rule 3 | C31: Readiness counts only Follow-through, Steadiness and Curiosity (six facets in the full report). Social energy and Warmth describe style, and neither end is better.
B32: Rule 4 | C32: 80 and above is the top band. We never tell anyone to aim for 100. A score of 100 means the top answer on every readiness question, which is the edge of the scale and not the goal.
B33: Rule 5 | C33: The cut points (40, 60 and 80 for bands, 40 and 60 for levels) are working values. We reset them with pilot data once at least 200 people have finished.
B34: Rule 6 | C34: A low area is always shown with one thing to try, never on its own.
B35: Rule 7 | C35: Results are for the person's own growth. We do not use them to hire, promote or rank people.
B36: Rule 8 | C36: Any change to these rules gets a new version and an entry in the change log.
B38: Sign-off
B39: Name | C39: Agree (Yes / No) | D39: Role | E39: Date | F39: Comments
B40: Wen-Szu

Sheet Area rubrics
B2: The five areas: definitions and rubrics
B3: Column E in the first table is the participant-facing definition. The website introduction to the five areas uses this text.
B5: Definitions
B6: Area | C6: Counts toward readiness | D6: Big Five name | E6: Definition (shown to participants) | F6: What it is not | G6: How to read the number | H6: Why it matters in a bigger role | I6: Questions that feed it
B7: Follow-through | C7: Yes | D7: Conscientiousness | E7: How reliably you plan your work, keep it organized and finish it without being chased. | F7: How smart or talented you are, or how many hours you put in. | G7: Higher means a stronger habit. Very high can tip into holding on to a plan after it stops working. | H7: Bigger roles come with less checking. People need to trust that what you own gets done. | I7: Free check: mini_c1; mini_c2 (reversed); mini_c3; mini_c4 (reversed). Full report adds: Achievement-Striving, Self-Discipline, Orderliness.
B8: Steadiness | C8: Yes | D8: Neuroticism, shown flipped (Emotional stability) | E8: How calm and clear you stay under pressure, and how fast you recover from a bad day. | F8: Whether you have feelings or hide them. Steady people feel stress too. It throws them off less. | G8: Higher means pressure throws you off less. Very high can mean missing how stressed other people are. | H8: Senior roles bring more pressure, and more people watch how you react to it. | I8: Free check: mini_n1; mini_n2 (reversed); mini_n3; mini_n4 (reversed). Full report adds: Anxiety and Self-Consciousness, both flipped.
B9: Curiosity | C9: Yes | D9: Intellect (Openness) | E9: How much you enjoy ideas, hard problems and learning new ways of doing things. | F9: An IQ score or a measure of how much schooling you have. | G9: Higher means you go after hard problems and new ideas. Very high can mean chasing what is interesting over what is important. | H9: Bigger roles bring problems with no playbook, and tools like AI keep changing how the work gets done. | I9: Free check: mini_i1; mini_i2 (reversed); mini_i3 (reversed); mini_i4 (reversed). Full report adds: Intellect.
B10: Social energy | C10: No. It sets your Voice (Reserved, Balanced or Vocal) | D10: Extraversion | E10: How much energy you get from being around people, and how readily you speak up and take the floor. | F10: How good you are with people, or whether you can lead. | G10: Neither end is better. It shows how you lead, from the front or one on one, and not whether you can. | H10: It shapes how people experience you as a leader, in the big meeting or in the quiet follow-up. | I10: Free check: mini_e1; mini_e2 (reversed); mini_e3; mini_e4 (reversed). Full report adds: Assertiveness (sets Voice in the full report), Activity Level.
B11: Warmth | C11: No. It is the connection side of your Drive | D11: Agreeableness | E11: How much you notice how others feel and how much effort you put into working well with them. | F11: Being nice, or being easy to push around. | G11: Neither end is better. Lower often means straight talk. Higher often means trust and loyalty. | H11: It shapes why people follow you, because they trust you or because you are clear and firm. | I11: Free check: mini_a1; mini_a2 (reversed); mini_a3; mini_a4 (reversed). Full report adds: Altruism (sets Drive in the full report), Cooperation.
B13: Level rubric for each area
B14: Low, Mid and High use the level cut points on the Scoring rules tab. Column E matches the result write-ups. Columns F to H are for coaches and for the full report.
B15: Area | C15: Level | D15: Score range | E15: What it looks like at work | F15: Use it for | G15: Watch for | H15: One thing to try | I15: Result page text (Write-ups tab)
B16: Follow-through | C16: Low | D16: ="0 to "&('Scoring rules'!C7-1) -> 0 to 39 | E16: You start strong, then things slip without a deadline or a reminder. Plans live in your head. | F16: Fast starts and plans that keep changing, where flexibility helps. | G16: Missed handoffs, and people having to chase you. | H16: Write tomorrow's three tasks down before you log off. Close each one before you start something new. | I16: You work best with room to move and may start more than you finish. Clear deadlines and simple systems tend to help you most.
B17: Follow-through | C17: Mid | D17: ='Scoring rules'!C7&" to "&'Scoring rules'!C8 -> 40 to 60 | E17: You get the important things done on time. Small details slide when you are busy. | F17: Work that mixes structure with change. | G17: The small loose ends that other people notice first. | H17: Keep one running list and clear it every Friday. | I17: You get the important things done and let smaller details slide when time is short.
B18: Follow-through | C18: High | D18: =('Scoring rules'!C8+1)&" to 100" -> 61 to 100 | E18: You finish what you start without being chased. People plan around you. | F18: Owning deadlines, handoffs and anything other people depend on. | G18: Holding on to a plan after it stops working, or doing it yourself when you should hand it off. | H18: Hand one task a week to someone else and let them do it their way. | I18: You finish what you start and people can plan around you. Loose ends bother you more than they bother most people.
B19: Steadiness | C19: Low | D19: ="0 to "&('Scoring rules'!C7-1) -> 0 to 39 | E19: Pressure reaches you fast. A bad meeting can stay with you for the rest of the day. | F19: Spotting risks early, because you feel them first. | G19: Decisions made while upset, and replaying mistakes. | H19: Before you reply to a tense message, wait ten minutes and write down the one thing you need from it. | I19: Pressure reaches you quickly and a bad moment can stay with you for a while. Knowing this helps you plan recovery time into hard weeks.
B20: Steadiness | C20: Mid | D20: ='Scoring rules'!C7&" to "&'Scoring rules'!C8 -> 40 to 60 | E20: You stay level most days. The hardest weeks still get to you. | F20: Normal pressure and ordinary deadlines. | G20: Stress that builds quietly over a long stretch. | H20: Put one recovery block into any week that has a big deadline. | I20: Most days you stay level. The really hard weeks still get to you, like they do for most people.
B21: Steadiness | C21: High | D21: =('Scoring rules'!C8+1)&" to 100" -> 61 to 100 | E21: You stay calm when things get loud. Other people borrow your calm. | F21: Crises, hard conversations and being the first to speak after bad news. | G21: Missing how stressed others are, or looking unbothered when it matters to them. | H21: In a tense moment, say how the room is feeling before you move to the fix. | I21: You stay calm when things get loud. The people around you often borrow some of that calm without realizing it.
B22: Curiosity | C22: Low | D22: ="0 to "&('Scoring rules'!C7-1) -> 0 to 39 | E22: You prefer ideas you can use tomorrow. You judge an idea by whether it works. | F22: Getting practical things done without overthinking them. | G22: Missing a better way because the current one still works. | H22: On one problem a week, ask why one more time than you usually would before you settle. | I22: You prefer ideas you can use tomorrow over theory. You judge an idea by whether it works in practice.
B23: Curiosity | C23: Mid | D23: ='Scoring rules'!C7&" to "&'Scoring rules'!C8 -> 40 to 60 | E23: You enjoy an idea when it connects to real work. | F23: Turning ideas into plans people can act on. | G23: Tuning out of longer strategy conversations. | H23: Read one piece a week from outside your field and link it to a problem you have now. | I23: You enjoy a good idea when it connects to something real and lose interest when it drifts too far from practice.
B24: Curiosity | C24: High | D24: =('Scoring rules'!C8+1)&" to 100" -> 61 to 100 | E24: You enjoy hard problems and new ideas for their own sake. You learn new tools fast. | F24: Strategy, problems with no playbook, and trying new tools first. | G24: Chasing the interesting thing over the important one, or going deep when a quick answer would do. | H24: For every new idea, write down the next step and who owns it. | I24: You enjoy complex problems and new ideas for their own sake. You may be the one still asking why after everyone else has moved on.
B25: Social energy | C25: Low | D25: ="0 to "&('Scoring rules'!C7-1) -> 0 to 39 | E25: You recharge on your own and speak once you have something worth saying. | F25: Deep work, listening and one-on-one conversations. | G25: Good ideas that stay unsaid in big meetings. | H25: Say one thing in the first ten minutes of every meeting. | I25: You recharge on your own and tend to speak once you have something worth saying. In a busy meeting you may be the one who listens longest.
B26: Social energy | C26: Mid | D26: ='Scoring rules'!C7&" to "&'Scoring rules'!C8 -> 40 to 60 | E26: You can work a room when you need to and still enjoy time alone. | F26: Switching between people work and focused solo work. | G26: Not choosing, so you neither lead the room nor protect your focus time. | H26: Before each meeting, decide whether you are there to lead or to listen. | I26: You can work a room when you need to and still enjoy time alone. Which way you lean depends on the day and the people.
B27: Social energy | C27: High | D27: =('Scoring rules'!C8+1)&" to 100" -> 61 to 100 | E27: You get energy from people and are often the first to start the conversation. | F27: Rallying people, building networks and leading from the front. | G27: Filling silences other people needed, or deciding before quieter people speak. | H27: In your next meeting, ask two people for their view before you give yours. | I27: You get energy from people. You are often the first to start a conversation and people notice when you are not there.
B28: Warmth | C28: Low | D28: ="0 to "&('Scoring rules'!C7-1) -> 0 to 39 | E28: You say what you think, even when people do not want to hear it. | F28: Hard calls, negotiations and honest feedback. | G28: People not bringing you problems early. | H28: Before you give hard feedback, name one thing the person did well. | I28: You say what you think even when it is not what people want to hear. Others may read you as tough before they read you as fair.
B29: Warmth | C29: Mid | D29: ='Scoring rules'!C7&" to "&'Scoring rules'!C8 -> 40 to 60 | E29: You care how people feel and can still hold a hard line. | F29: Managing people through change. | G29: Going soft or hard depending on your mood instead of the situation. | H29: Before a hard conversation, decide what the person needs from you. | I29: You care about how people feel and you can still hold a hard line when it matters.
B30: Warmth | C30: High | D30: =('Scoring rules'!C8+1)&" to 100" -> 61 to 100 | E30: You notice how people feel and act on it. Colleagues come to you when something is wrong. | F30: Building trust, mentoring and keeping a team together. | G30: Avoiding a hard call to keep the peace, or taking on other people's work. | H30: This week, say no to one request that someone else should own. | I30: You notice how people are feeling and you often act on it. Colleagues likely come to you when something is not going well.

Sheet Scoring rules
B2: Scoring rules
B3: How answers become scores. Blue cells on yellow are settings you can change to see how results move.
B5: Settings
B6: Setting | C6: Value | F6: What it does
B7: Level cut, low | C7: 40 | F7: A score below this reads as Low
B8: Level cut, high | C8: 60 | F8: A score above this reads as High. Between the two reads as Mid
B9: Voice cut, Reserved below | C9: 40 | F9: Voice score below this is Reserved
B10: Voice cut, Vocal above | C10: 60 | F10: Voice score above this is Vocal. Between the two is Balanced
B11: Drive close call gap | C11: 10 | F11: If the two Drive scores are closer than this, the result flags a close call
B14: Readiness bands
B15: Band | C15: From score | F15: Note
B16: Emerging | C16: 0 | F16: Band names from the strategy deck. Cut points are working values
B17: Developing | C17: 40
B18: Strong | C18: 60
B19: Exceptional | C19: 80
B22: How the scoring works, step by step
B23: 1. Each answer is 1 to 5, from Very inaccurate to Very accurate.
B24: 2. Items marked minus are reverse scored, so a 5 becomes a 1 and a 2 becomes a 4. This happens in the Scored column of each test tab.
B25: 3. Each area or facet score is the average of its scored items, turned into 0 to 100 with (average minus 1) divided by 4, times 100.
B26: 4. Neuroticism is shown flipped as Steadiness (100 minus the score) so that higher always reads as more ready.
B27: 5. Free readiness score is the plain average of Follow-through, Steadiness and Curiosity.
B28: 6. Paid readiness score is the plain average of the six readiness facets, with Anxiety and Self-Consciousness flipped.
B29: 7. Voice comes from Social energy in the free preview and from Assertiveness in the paid report.
B30: 8. Drive compares Follow-through with Warmth in the free preview, and Achievement-Striving with Altruism in the paid report. The higher one wins.
B33: Where the items come from
B34: Scale | C34: Group | D34: Items used | E34: Alpha, full scale | F34: Source
B35: Mini-IPIP five areas | C35: Free tier | D35: 20 (4 per area) | E35: About .65 to .77 | F35: Donnellan, Oswald, Baird and Lucas (2006), Psychological Assessment 18(2). Public domain IPIP items
B36: Achievement-Striving | C36: Readiness | D36: 4 of 10 | E36: 0.78 | F36: IPIP NEO facet scale, ipip.ori.org (Goldberg). Alpha is for the full 10 item version
B37: Self-Discipline | C37: Readiness | D37: 4 of 10 | E37: 0.85 | F37: IPIP NEO facet scale, ipip.ori.org (Goldberg). Alpha is for the full 10 item version
B38: Orderliness | C38: Readiness | D38: 4 of 10 | E38: 0.82 | F38: IPIP NEO facet scale, ipip.ori.org (Goldberg). Alpha is for the full 10 item version
B39: Intellect | C39: Readiness | D39: 4 of 10 | E39: 0.86 | F39: IPIP NEO facet scale, ipip.ori.org (Goldberg). Alpha is for the full 10 item version
B40: Anxiety | C40: Readiness, read inversely | D40: 4 of 10 | E40: 0.83 | F40: IPIP NEO facet scale, ipip.ori.org (Goldberg). Alpha is for the full 10 item version
B41: Self-Consciousness | C41: Readiness, read inversely | D41: 4 of 10 | E41: 0.8 | F41: IPIP NEO facet scale, ipip.ori.org (Goldberg). Alpha is for the full 10 item version
B42: Assertiveness | C42: Style, the Voice axis | D42: 4 of 10 | E42: 0.84 | F42: IPIP NEO facet scale, ipip.ori.org (Goldberg). Alpha is for the full 10 item version
B43: Activity Level | C43: Style | D43: 4 of 10 | E43: 0.71 | F43: IPIP NEO facet scale, ipip.ori.org (Goldberg). Alpha is for the full 10 item version
B44: Cooperation | C44: Style | D44: 4 of 10 | E44: 0.73 | F44: IPIP NEO facet scale, ipip.ori.org (Goldberg). Alpha is for the full 10 item version
B45: Altruism | C45: Style, the Drive axis | D45: 4 of 10 | E45: 0.77 | F45: IPIP NEO facet scale, ipip.ori.org (Goldberg). Alpha is for the full 10 item version
B48: Open questions to settle before the pilot
B49: 1. Scores are a straight line conversion of the 1 to 5 average. The strategy deck calls for population norms, which we can only build from pilot data.
B50: 2. Every facet here uses 4 of its 10 IPIP items. Short scales usually have lower alpha than the full scale figures above, so each one needs checking in the pilot.
...

Sheet Write-ups
B2: Write-up library
B3: Every sentence the results can show. Edit the text here and the results update. Keys in column B are what the formulas look up, so leave them as they are.
B5: Area snapshot text (free result)
B6: Key | C6: Area | D6: Level | E6: Text
B7: Social energy|Low | C7: Social energy | D7: Low | E7: You recharge on your own and tend to speak once you have something worth saying. In a busy meeting you may be the one who listens longest.
B8: Social energy|Mid | C8: Social energy | D8: Mid | E8: You can work a room when you need to and still enjoy time alone. Which way you lean depends on the day and the people.
B9: Social energy|High | C9: Social energy | D9: High | E9: You get energy from people. You are often the first to start a conversation and people notice when you are not there.
B10: Warmth|Low | C10: Warmth | D10: Low | E10: You say what you think even when it is not what people want to hear. Others may read you as tough before they read you as fair.
B11: Warmth|Mid | C11: Warmth | D11: Mid | E11: You care about how people feel and you can still hold a hard line when it matters.
B12: Warmth|High | C12: Warmth | D12: High | E12: You notice how people are feeling and you often act on it. Colleagues likely come to you when something is not going well.
B13: Follow-through|Low | C13: Follow-through | D13: Low | E13: You work best with room to move and may start more than you finish. Clear deadlines and simple systems tend to help you most.
B14: Follow-through|Mid | C14: Follow-through | D14: Mid | E14: You get the important things done and let smaller details slide when time is short.
B15: Follow-through|High | C15: Follow-through | D15: High | E15: You finish what you start and people can plan around you. Loose ends bother you more than they bother most people.
B16: Steadiness|Low | C16: Steadiness | D16: Low | E16: Pressure reaches you quickly and a bad moment can stay with you for a while. Knowing this helps you plan recovery time into hard weeks.
B17: Steadiness|Mid | C17: Steadiness | D17: Mid | E17: Most days you stay level. The really hard weeks still get to you, like they do for most people.
... B21: Curiosity|High | C21: Curiosity | D21: High | E21: You enjoy complex problems and new ideas for their own sake. You may be the one still asking why after everyone else has moved on.
B23: Readiness band text
B24: Band | E24: Text
B25: Emerging | E25: Several of the habits that carry people into bigger roles are still forming for you. The facet report shows which ones to start with.
B26: Developing | E26: You have a working base and a few clear gaps. Closing one or two of them would move your score the most.
B27: Strong | E27: Most of the habits that matter are already in place. The next gains come from sharpening one or two specific areas.
B28: Exceptional | E28: Your answers show the habits of someone ready for a bigger role today. The question now is where to point them.
B30: Readiness profiles (Voice x Drive)
B31: Key | C31: Voice | D31: Drive | E31: Name | F31: Where you add the most | G31: What to watch | H31: Description | I31: In a few words | J31: Other names to test | K31: Previous name
B32: Reserved|Achievement-driven | C32: Reserved | D32: Achievement-driven | E32: Quiet achiever | F32: Work that needs finishing without anyone checking in. Your track record speaks before you do. | G32: Good work can go unseen. Tell people what you finished, not only what you are working on. | H32: You put in the work before anyone asks. People know you by what you finish, not by how much you talk about it. | I32: Focused, self-driven, reliable | J32: Heads-down doer · Self-starter | K32: The Quiet Climber
B33: Reserved|Connection-driven | C33: Reserved | D33: Connection-driven | E33: Steady supporter | F33: Tense moments and teams under strain. People calm down when you are in the room. | G33: You may carry other people's stress without saying so. Check in on your own load too. | H33: People lean on you when things get hard. You do not need the spotlight to make a team work better. | I33: Calm, dependable, loyal | J33: Calm and dependable · Rock of the team | K33: The Steady Anchor
B34: Balanced|Achievement-driven | C34: Balanced | D34: Achievement-driven | E34: Go-getter | F34: Goals that need both push and judgment. You know when to press and when to wait. | G34: You may try to play both roles at once. Decide which one the moment actually needs. | H34: You push hard for results and still read the room well enough to know when to ease off. | I34: Driven, practical, adaptable | J34: Driven all-rounder · Doer | K34: The Grounded Striver
B35: Balanced|Connection-driven | C35: Balanced | D35: Connection-driven | E35: Team player | F35: Work across teams where people talk past each other. | G35: Keeping the peace can delay a hard call. Some decisions need you to pick a side. | H35: You keep a group working together. You often notice what two people missed about each other. | I35: Cooperative, fair, easy to work with | J35: Collaborator · Connector | K35: The Bridge Builder
B36: Vocal|Achievement-driven | C36: Vocal | D36: Achievement-driven | E36: Natural leader | F36: New projects and moments that need someone to go first. | G36: Others may wait for you instead of stepping up. Leave room for them to lead. | H36: You go first and set the pace. Other people often take their cue from you. | I36: Decisive, confident, ambitious | J36: Take-charge type · Trailblazer | K36: The Pacesetter
B37: Vocal|Connection-driven | C37: Vocal | D37: Connection-driven | E37: People person | F37: Rallying people around a change or a new direction. | G37: Energy can run ahead of the plan. Pair your pull with someone who tracks the details. | H37: You bring energy into a room and get people talking to each other, not only to you. | I37: Outgoing, warm, encouraging | J37: Motivator · Energizer | K37: The Catalyst
B39: Strength and growth edge phrases (readiness facets only)
B40: Facet | E40: Strength (when this facet is a high point) | F40: Growth edge (when this facet is a low point)
B41: Achievement-Striving | E41: You set a high bar for your own work and keep pushing toward it. | F41: You may do what is asked and stop there. Picking one goal to push past is a good place to start.
B42: Self-Discipline | E42: You follow through on commitments without needing a reminder. | F42: Structure helps you more than open-ended ownership does.
B43: Orderliness | E43: You keep your work organized, so others can pick it up and understand it. | F43: A simple system for tracking tasks would give back time you now lose to searching and redoing.
B44: Intellect | E44: You enjoy hard problems and can hold a lot of information at once. | F44: You may reach for the quick answer when a decision deserves another hour of thinking.
B45: Anxiety | E45: A high-stakes meeting does not throw off your thinking. | F45: A tense meeting can stay with you longer than it should.
B46: Self-Consciousness | E46: You are comfortable speaking up in rooms where you are the least senior person. | F46: You may hold back in unfamiliar settings until you feel sure. Speaking earlier, even briefly, gets your thinking into the room.
B48: Working style text (style facets, described without judgment)
B49: Key | C49: Facet | D49: Level | E49: Text
...
